2023-07-13 02:43:36,250: [11] m.main:INFO: Registered plugins: IntrospectionAPIPlugin, <class 'manticore.ethereum.plugins.SkipRevertBasicBlocks'>, <class 'manticore.ethereum.plugins.FilterFunctions'>
2023-07-13 02:43:36,250: [11] m.main:INFO: Beginning analysis
2023-07-13 02:43:36,256: [11] m.e.manticore:INFO: Starting symbolic create contract
2023-07-13 02:43:37,280: [11] m.e.manticore:INFO: Starting symbolic transaction: 0
2023-07-13 02:43:47,171: [11] m.c.worker:ERROR: Exception in state 3: ManticoreError('Forking on unfeasible constraint set')
Traceback (most recent call last):
  File "/usr/local/lib/python3.7/dist-packages/manticore/core/worker.py", line 137, in run
    current_state.execute()
  File "/usr/local/lib/python3.7/dist-packages/manticore/ethereum/state.py", line 8, in execute
    return self._platform.execute()
  File "/usr/local/lib/python3.7/dist-packages/manticore/platforms/evm.py", line 3106, in execute
    self.current_vm.execute()
  File "/usr/local/lib/python3.7/dist-packages/manticore/platforms/evm.py", line 1322, in execute
    raise Concretize("Symbolic PC", expression=expression, setstate=setstate, policy="ALL")
manticore.core.state.Concretize

During handling of the above exception, another exception occurred:

Traceback (most recent call last):
  File "/usr/local/lib/python3.7/dist-packages/manticore/core/worker.py", line 158, in run
    m._fork(current_state, exc.expression, exc.policy, exc.setstate, exc.values)
  File "/usr/local/lib/python3.7/dist-packages/manticore/core/manticore.py", line 518, in _fork
    raise ManticoreError("Forking on unfeasible constraint set")
manticore.exceptions.ManticoreError: Forking on unfeasible constraint set
 
2023-07-13 02:43:48,230: [11] m.e.manticore:INFO: 1 alive states, 2 terminated states
2023-07-13 02:43:48,729: [11] m.e.manticore:INFO: Starting symbolic transaction: 1
2023-07-13 02:43:59,125: [11] m.c.worker:ERROR: Exception in state 9: ManticoreError('Forking on unfeasible constraint set')
Traceback (most recent call last):
  File "/usr/local/lib/python3.7/dist-packages/manticore/core/worker.py", line 137, in run
    current_state.execute()
  File "/usr/local/lib/python3.7/dist-packages/manticore/ethereum/state.py", line 8, in execute
    return self._platform.execute()
  File "/usr/local/lib/python3.7/dist-packages/manticore/platforms/evm.py", line 3106, in execute
    self.current_vm.execute()
  File "/usr/local/lib/python3.7/dist-packages/manticore/platforms/evm.py", line 1322, in execute
    raise Concretize("Symbolic PC", expression=expression, setstate=setstate, policy="ALL")
manticore.core.state.Concretize

During handling of the above exception, another exception occurred:

Traceback (most recent call last):
  File "/usr/local/lib/python3.7/dist-packages/manticore/core/worker.py", line 158, in run
    m._fork(current_state, exc.expression, exc.policy, exc.setstate, exc.values)
  File "/usr/local/lib/python3.7/dist-packages/manticore/core/manticore.py", line 518, in _fork
    raise ManticoreError("Forking on unfeasible constraint set")
manticore.exceptions.ManticoreError: Forking on unfeasible constraint set
 
2023-07-13 02:44:00,408: [11] m.e.manticore:INFO: 1 alive states, 3 terminated states
2023-07-13 02:44:00,947: [11] m.e.manticore:INFO: Starting symbolic transaction: 2
2023-07-13 02:44:12,497: [11] m.c.worker:ERROR: Exception in state 6: ManticoreError('Forking on unfeasible constraint set')
Traceback (most recent call last):
  File "/usr/local/lib/python3.7/dist-packages/manticore/core/worker.py", line 137, in run
    current_state.execute()
  File "/usr/local/lib/python3.7/dist-packages/manticore/ethereum/state.py", line 8, in execute
    return self._platform.execute()
  File "/usr/local/lib/python3.7/dist-packages/manticore/platforms/evm.py", line 3106, in execute
    self.current_vm.execute()
  File "/usr/local/lib/python3.7/dist-packages/manticore/platforms/evm.py", line 1322, in execute
    raise Concretize("Symbolic PC", expression=expression, setstate=setstate, policy="ALL")
manticore.core.state.Concretize

During handling of the above exception, another exception occurred:

Traceback (most recent call last):
  File "/usr/local/lib/python3.7/dist-packages/manticore/core/worker.py", line 158, in run
    m._fork(current_state, exc.expression, exc.policy, exc.setstate, exc.values)
  File "/usr/local/lib/python3.7/dist-packages/manticore/core/manticore.py", line 518, in _fork
    raise ManticoreError("Forking on unfeasible constraint set")
manticore.exceptions.ManticoreError: Forking on unfeasible constraint set
 
2023-07-13 02:44:13,421: [11] m.e.manticore:INFO: 1 alive states, 4 terminated states
2023-07-13 02:44:14,092: [106] m.c.manticore:INFO: Generated testcase No. 0 - STOP(4 txs)
2023-07-13 02:44:14,093: [106] m.c.plugin:WARNING: Caught will_solve in state None, but failed to capture its initialization
2023-07-13 02:44:17,589: [11] m.c.manticore:INFO: Results in /mcore_vrtw6pts
2023-07-13 02:44:17,589: [11] m.c.manticore:INFO: Total time: 16.618240118026733
