{"success": false, "error": "Traceback (most recent call last):\n  File \"/usr/lib/python3/dist-packages/urllib3/connection.py\", line 159, in _new_conn\n    conn = connection.create_connection(\n  File \"/usr/lib/python3/dist-packages/urllib3/util/connection.py\", line 61, in create_connection\n    for res in socket.getaddrinfo(host, port, family, socket.SOCK_STREAM):\n  File \"/usr/lib/python3.8/socket.py\", line 918, in getaddrinfo\n    for res in _socket.getaddrinfo(host, port, family, type, proto, flags):\nsocket.gaierror: [Errno -3] Temporary failure in name resolution\n\nDuring handling of the above exception, another exception occurred:\n\nTraceback (most recent call last):\n  File \"/usr/lib/python3/dist-packages/urllib3/connectionpool.py\", line 665, in urlopen\n    httplib_response = self._make_request(\n  File \"/usr/lib/python3/dist-packages/urllib3/connectionpool.py\", line 376, in _make_request\n    self._validate_conn(conn)\n  File \"/usr/lib/python3/dist-packages/urllib3/connectionpool.py\", line 996, in _validate_conn\n    conn.connect()\n  File \"/usr/lib/python3/dist-packages/urllib3/connection.py\", line 314, in connect\n    conn = self._new_conn()\n  File \"/usr/lib/python3/dist-packages/urllib3/connection.py\", line 171, in _new_conn\n    raise NewConnectionError(\nurllib3.exceptions.NewConnectionError: <urllib3.connection.VerifiedHTTPSConnection object at 0x7f14cadf5610>: Failed to establish a new connection: [Errno -3] Temporary failure in name resolution\n\nDuring handling of the above exception, another exception occurred:\n\nTraceback (most recent call last):\n  File \"/usr/lib/python3/dist-packages/requests/adapters.py\", line 439, in send\n    resp = conn.urlopen(\n  File \"/usr/lib/python3/dist-packages/urllib3/connectionpool.py\", line 719, in urlopen\n    retries = retries.increment(\n  File \"/usr/lib/python3/dist-packages/urllib3/util/retry.py\", line 436, in increment\n    raise MaxRetryError(_pool, url, error or ResponseError(cause))\nurllib3.exceptions.MaxRetryError: HTTPSConnectionPool(host='solc-bin.ethereum.org', port=443): Max retries exceeded with url: /linux-amd64/list.json (Caused by NewConnectionError('<urllib3.connection.VerifiedHTTPSConnection object at 0x7f14cadf5610>: Failed to establish a new connection: [Errno -3] Temporary failure in name resolution'))\n\nDuring handling of the above exception, another exception occurred:\n\nTraceback (most recent call last):\n  File \"/usr/local/lib/python3.8/dist-packages/mythril-0.23.15-py3.8.egg/mythril/interfaces/cli.py\", line 943, in parse_args_and_execute\n    address = load_code(disassembler, args)\n  File \"/usr/local/lib/python3.8/dist-packages/mythril-0.23.15-py3.8.egg/mythril/interfaces/cli.py\", line 698, in load_code\n    address, _ = disassembler.load_from_solidity(\n  File \"/usr/local/lib/python3.8/dist-packages/mythril-0.23.15-py3.8.egg/mythril/mythril/mythril_disassembler.py\", line 172, in load_from_solidity\n    solc_binary = self.solc_binary or util.extract_binary(file)\n  File \"/usr/local/lib/python3.8/dist-packages/mythril-0.23.15-py3.8.egg/mythril/ethereum/util.py\", line 181, in extract_binary\n    return solc_exists(version)\n  File \"/usr/local/lib/python3.8/dist-packages/mythril-0.23.15-py3.8.egg/mythril/ethereum/util.py\", line 137, in solc_exists\n    solcx.install_solc(\"v\" + version)\n  File \"/usr/local/lib/python3.8/dist-packages/solcx/install.py\", line 441, in install_solc\n    data = requests.get(BINARY_DOWNLOAD_BASE.format(_get_os_name(), \"list.json\"))\n  File \"/usr/lib/python3/dist-packages/requests/api.py\", line 75, in get\n    return request('get', url, params=params, **kwargs)\n  File \"/usr/lib/python3/dist-packages/requests/api.py\", line 60, in request\n    return session.request(method=method, url=url, **kwargs)\n  File \"/usr/lib/python3/dist-packages/requests/sessions.py\", line 533, in request\n    resp = self.send(prep, **send_kwargs)\n  File \"/usr/lib/python3/dist-packages/requests/sessions.py\", line 646, in send\n    r = adapter.send(request, **kwargs)\n  File \"/usr/lib/python3/dist-packages/requests/adapters.py\", line 516, in send\n    raise ConnectionError(e, request=request)\nrequests.exceptions.ConnectionError: HTTPSConnectionPool(host='solc-bin.ethereum.org', port=443): Max retries exceeded with url: /linux-amd64/list.json (Caused by NewConnectionError('<urllib3.connection.VerifiedHTTPSConnection object at 0x7f14cadf5610>: Failed to establish a new connection: [Errno -3] Temporary failure in name resolution'))\n", "issues": []}
